<?xml version='1.0' encoding='UTF-8'?>
<sdf version="1.7">
  <model name="x_quad_drone_generated">
    <static>false</static>
    <pose>0 0 1.0 0 0 0</pose>
    <link name="hull">
      <pose>0 0 0 0 0 0</pose>
      <inertial>
        <mass>0.272000</mass>
        <inertia>
          <ixx>5.66666667e-05</ixx>
          <iyy>5.66666667e-05</iyy>
          <izz>7.25333333e-05</izz>
          <ixy>0</ixy><ixz>0</ixz><iyz>0</iyz>
        </inertia>
      </inertial>
      <collision name="hull_geom_col">
        <geometry><box><size>0.040000 0.040000 0.030000</size></box></geometry>
      </collision>
      <visual name="hull_geom_vis">
        <geometry><box><size>0.040000 0.040000 0.030000</size></box></geometry>
        <material><script><uri>file://media/materials/scripts/gazebo.material</uri><name>Gazebo/Grey</name></script></material>
      </visual>
    </link>
    <link name="arm_0">
      <pose>0.038900 -0.038900 0.000000 0 0 -0.785398</pose>
      <inertial>
        <mass>0.014438</mass>
        <inertia>
          <ixx>3.00781250e-07</ixx>
          <iyy>1.45947244e-05</iyy>
          <izz>1.48353494e-05</izz>
          <ixy>0</ixy><ixz>0</ixz><iyz>0</iyz>
        </inertia>
      </inertial>
      <collision name="arm_0_geom_col">
        <geometry><box><size>0.110026 0.015000 0.005000</size></box></geometry>
      </collision>
      <visual name="arm_0_geom_vis">
        <geometry><box><size>0.110026 0.015000 0.005000</size></box></geometry>
        <material><script><uri>file://media/materials/scripts/gazebo.material</uri><name>Gazebo/DarkGrey</name></script></material>
      </visual>
    </link>
    <joint name="joint_hull_to_arm_0" type="fixed">
      <parent>hull</parent>
      <child>arm_0</child>
      <pose>0 0 0 0 0 0</pose>
    </joint>
    <link name="rotor_0">
      <pose>0.077800 -0.077800 0.000000 0 0 -0.785398</pose>
      <inertial>
        <mass>0.039000</mass>
        <inertia>
          <ixx>3.96394375e-05</ixx>
          <iyy>3.96394375e-05</iyy>
          <izz>7.86288750e-05</izz>
          <ixy>0</ixy><ixz>0</ixz><iyz>0</iyz>
        </inertia>
      </inertial>
      <collision name="rotor_0_geom_col">
        <geometry><cylinder><radius>0.063500</radius><length>0.010000</length></cylinder></geometry>
      </collision>
      <visual name="rotor_0_geom_vis">
        <geometry><cylinder><radius>0.063500</radius><length>0.010000</length></cylinder></geometry>
        <material><script><uri>file://media/materials/scripts/gazebo.material</uri><name>Gazebo/Red</name></script></material>
      </visual>
    </link>
    <joint name="joint_arm_0_to_rotor_0" type="revolute">
      <parent>arm_0</parent>
      <child>rotor_0</child>
      <pose>0.055013 0 0.000000 0 0 0</pose>
      <axis><xyz>0 0 1</xyz><limit><lower>-1e16</lower><upper>1e16</upper></limit><dynamics><damping>0.001</damping></dynamics></axis>
    </joint>
    <link name="arm_1">
      <pose>-0.038900 0.038900 0.000000 0 0 2.356194</pose>
      <inertial>
        <mass>0.014438</mass>
        <inertia>
          <ixx>3.00781250e-07</ixx>
          <iyy>1.45947244e-05</iyy>
          <izz>1.48353494e-05</izz>
          <ixy>0</ixy><ixz>0</ixz><iyz>0</iyz>
        </inertia>
      </inertial>
      <collision name="arm_1_geom_col">
        <geometry><box><size>0.110026 0.015000 0.005000</size></box></geometry>
      </collision>
      <visual name="arm_1_geom_vis">
        <geometry><box><size>0.110026 0.015000 0.005000</size></box></geometry>
        <material><script><uri>file://media/materials/scripts/gazebo.material</uri><name>Gazebo/DarkGrey</name></script></material>
      </visual>
    </link>
    <joint name="joint_hull_to_arm_1" type="fixed">
      <parent>hull</parent>
      <child>arm_1</child>
      <pose>0 0 0 0 0 0</pose>
    </joint>
    <link name="rotor_1">
      <pose>-0.077800 0.077800 0.000000 0 0 2.356194</pose>
      <inertial>
        <mass>0.039000</mass>
        <inertia>
          <ixx>3.96394375e-05</ixx>
          <iyy>3.96394375e-05</iyy>
          <izz>7.86288750e-05</izz>
          <ixy>0</ixy><ixz>0</ixz><iyz>0</iyz>
        </inertia>
      </inertial>
      <collision name="rotor_1_geom_col">
        <geometry><cylinder><radius>0.063500</radius><length>0.010000</length></cylinder></geometry>
      </collision>
      <visual name="rotor_1_geom_vis">
        <geometry><cylinder><radius>0.063500</radius><length>0.010000</length></cylinder></geometry>
        <material><script><uri>file://media/materials/scripts/gazebo.material</uri><name>Gazebo/Red</name></script></material>
      </visual>
    </link>
    <joint name="joint_arm_1_to_rotor_1" type="revolute">
      <parent>arm_1</parent>
      <child>rotor_1</child>
      <pose>0.055013 0 0.000000 0 0 0</pose>
      <axis><xyz>0 0 1</xyz><limit><lower>-1e16</lower><upper>1e16</upper></limit><dynamics><damping>0.001</damping></dynamics></axis>
    </joint>
    <link name="arm_2">
      <pose>0.038900 0.038900 0.000000 0 0 0.785398</pose>
      <inertial>
        <mass>0.014438</mass>
        <inertia>
          <ixx>3.00781250e-07</ixx>
          <iyy>1.45947244e-05</iyy>
          <izz>1.48353494e-05</izz>
          <ixy>0</ixy><ixz>0</ixz><iyz>0</iyz>
        </inertia>
      </inertial>
      <collision name="arm_2_geom_col">
        <geometry><box><size>0.110026 0.015000 0.005000</size></box></geometry>
      </collision>
      <visual name="arm_2_geom_vis">
        <geometry><box><size>0.110026 0.015000 0.005000</size></box></geometry>
        <material><script><uri>file://media/materials/scripts/gazebo.material</uri><name>Gazebo/DarkGrey</name></script></material>
      </visual>
    </link>
    <joint name="joint_hull_to_arm_2" type="fixed">
      <parent>hull</parent>
      <child>arm_2</child>
      <pose>0 0 0 0 0 0</pose>
    </joint>
    <link name="rotor_2">
      <pose>0.077800 0.077800 0.000000 0 0 0.785398</pose>
      <inertial>
        <mass>0.039000</mass>
        <inertia>
          <ixx>3.96394375e-05</ixx>
          <iyy>3.96394375e-05</iyy>
          <izz>7.86288750e-05</izz>
          <ixy>0</ixy><ixz>0</ixz><iyz>0</iyz>
        </inertia>
      </inertial>
      <collision name="rotor_2_geom_col">
        <geometry><cylinder><radius>0.063500</radius><length>0.010000</length></cylinder></geometry>
      </collision>
      <visual name="rotor_2_geom_vis">
        <geometry><cylinder><radius>0.063500</radius><length>0.010000</length></cylinder></geometry>
        <material><script><uri>file://media/materials/scripts/gazebo.material</uri><name>Gazebo/Red</name></script></material>
      </visual>
    </link>
    <joint name="joint_arm_2_to_rotor_2" type="revolute">
      <parent>arm_2</parent>
      <child>rotor_2</child>
      <pose>0.055013 0 0.000000 0 0 0</pose>
      <axis><xyz>0 0 1</xyz><limit><lower>-1e16</lower><upper>1e16</upper></limit><dynamics><damping>0.001</damping></dynamics></axis>
    </joint>
    <link name="arm_3">
      <pose>-0.038900 -0.038900 0.000000 0 0 -2.356194</pose>
      <inertial>
        <mass>0.014438</mass>
        <inertia>
          <ixx>3.00781250e-07</ixx>
          <iyy>1.45947244e-05</iyy>
          <izz>1.48353494e-05</izz>
          <ixy>0</ixy><ixz>0</ixz><iyz>0</iyz>
        </inertia>
      </inertial>
      <collision name="arm_3_geom_col">
        <geometry><box><size>0.110026 0.015000 0.005000</size></box></geometry>
      </collision>
      <visual name="arm_3_geom_vis">
        <geometry><box><size>0.110026 0.015000 0.005000</size></box></geometry>
        <material><script><uri>file://media/materials/scripts/gazebo.material</uri><name>Gazebo/DarkGrey</name></script></material>
      </visual>
    </link>
    <joint name="joint_hull_to_arm_3" type="fixed">
      <parent>hull</parent>
      <child>arm_3</child>
      <pose>0 0 0 0 0 0</pose>
    </joint>
    <link name="rotor_3">
      <pose>-0.077800 -0.077800 0.000000 0 0 -2.356194</pose>
      <inertial>
        <mass>0.039000</mass>
        <inertia>
          <ixx>3.96394375e-05</ixx>
          <iyy>3.96394375e-05</iyy>
          <izz>7.86288750e-05</izz>
          <ixy>0</ixy><ixz>0</ixz><iyz>0</iyz>
        </inertia>
      </inertial>
      <collision name="rotor_3_geom_col">
        <geometry><cylinder><radius>0.063500</radius><length>0.010000</length></cylinder></geometry>
      </collision>
      <visual name="rotor_3_geom_vis">
        <geometry><cylinder><radius>0.063500</radius><length>0.010000</length></cylinder></geometry>
        <material><script><uri>file://media/materials/scripts/gazebo.material</uri><name>Gazebo/Red</name></script></material>
      </visual>
    </link>
    <joint name="joint_arm_3_to_rotor_3" type="revolute">
      <parent>arm_3</parent>
      <child>rotor_3</child>
      <pose>0.055013 0 0.000000 0 0 0</pose>
      <axis><xyz>0 0 1</xyz><limit><lower>-1e16</lower><upper>1e16</upper></limit><dynamics><damping>0.001</damping></dynamics></axis>
    </joint>
    <plugin name="trick_executor_plugin" filename="libtrick_executor_plugin.so">
      <rotor_count>4</rotor_count>
      <rotor_link_base_name>rotor_</rotor_link_base_name>
      <zmq_port>5555</zmq_port>
      <run_test_mode>true</run_test_mode>
      <test_mode_radius>2.000000</test_mode_radius>
      <test_mode_angular_velocity>0.500000</test_mode_angular_velocity>
      <test_mode_altitude>1.500000</test_mode_altitude>
      <drag_coefficient>0.100000</drag_coefficient>
    </plugin>
  </model>
</sdf>