<?xml version='1.0' encoding='UTF-8'?>
<sdf version="1.7"><model name="tesseract_nano"><static>false</static><link name="hull"><pose>0 0 0.00500 0 0 0</pose><inertial><mass>0.020000</mass><inertia><ixx>1.20833333e-06</ixx><iyy>4.33333333e-06</iyy><izz>5.20833333e-06</izz><ixy>0</ixy><ixz>0</ixz><iyz>0</iyz></inertia></inertial><collision name="hull_geom_col"><geometry><box><size>0.050000 0.025000 0.010000</size></box></geometry></collision><visual name="hull_geom_vis"><geometry><box><size>0.050000 0.025000 0.010000</size></box></geometry><material><script><uri>file://media/materials/scripts/gazebo.material</uri><name>Gazebo/Grey</name></script></material></visual></link><link name="arm_0"><pose>0.05500 0.00000 0.00500 0 0 0.00000</pose><inertial><mass>0.000864</mass><inertia><ixx>1.29600000e-09</ixx><iyy>2.59848000e-07</iyy><izz>2.59848000e-07</izz><ixy>0</ixy><ixz>0</ixz><iyz>0</iyz></inertia></inertial><collision name="arm_0_geom_col"><geometry><box><size>0.060000 0.003000 0.003000</size></box></geometry></collision><visual name="arm_0_geom_vis"><geometry><box><size>0.060000 0.003000 0.003000</size></box></geometry><material><script><uri>file://media/materials/scripts/gazebo.material</uri><name>Gazebo/Grey</name></script></material></visual></link><joint name="arm_0_fixed_joint" type="fixed"><parent>hull</parent><child>arm_0</child><pose>0.02500 0.00000 0 0 0 0.00000</pose></joint><link name="rotor_0"><pose>0.08500 0.00000 0.00500 0 0 0.00000</pose><inertial><mass>0.015000</mass><inertia><ixx>9.32187500e-07</ixx><iyy>9.32187500e-07</iyy><izz>1.80187500e-06</izz><ixy>0</ixy><ixz>0</ixz><iyz>0</iyz></inertia></inertial><collision name="rotor_0_geom_col"><geometry><cylinder><radius>0.015500</radius><length>0.005000</length></cylinder></geometry></collision><visual name="rotor_0_geom_vis"><geometry><cylinder><radius>0.015500</radius><length>0.005000</length></cylinder></geometry><material><script><uri>file://media/materials/scripts/gazebo.material</uri><name>Gazebo/DarkGrey</name></script></material></visual></link><joint name="rotor_0_revolute_joint" type="revolute"><pose relative_to="arm_0">0.03000 0 0 0 0 0</pose><parent>arm_0</parent><child>rotor_0</child><axis><xyz>0 0 1</xyz><limit><lower>-1.79769e+308</lower><upper>1.79769e+308</upper></limit><dynamics><damping>1.00e-05</damping></dynamics></axis></joint><link name="arm_1"><pose>0.00000 0.04250 0.00500 0 0 1.57080</pose><inertial><mass>0.000864</mass><inertia><ixx>1.29600000e-09</ixx><iyy>2.59848000e-07</iyy><izz>2.59848000e-07</izz><ixy>0</ixy><ixz>0</ixz><iyz>0</iyz></inertia></inertial><collision name="arm_1_geom_col"><geometry><box><size>0.060000 0.003000 0.003000</size></box></geometry></collision><visual name="arm_1_geom_vis"><geometry><box><size>0.060000 0.003000 0.003000</size></box></geometry><material><script><uri>file://media/materials/scripts/gazebo.material</uri><name>Gazebo/Grey</name></script></material></visual></link><joint name="arm_1_fixed_joint" type="fixed"><parent>hull</parent><child>arm_1</child><pose>0.00000 0.01250 0 0 0 1.57080</pose></joint><link name="rotor_1"><pose>0.00000 0.07250 0.00500 0 0 1.57080</pose><inertial><mass>0.015000</mass><inertia><ixx>9.32187500e-07</ixx><iyy>9.32187500e-07</iyy><izz>1.80187500e-06</izz><ixy>0</ixy><ixz>0</ixz><iyz>0</iyz></inertia></inertial><collision name="rotor_1_geom_col"><geometry><cylinder><radius>0.015500</radius><length>0.005000</length></cylinder></geometry></collision><visual name="rotor_1_geom_vis"><geometry><cylinder><radius>0.015500</radius><length>0.005000</length></cylinder></geometry><material><script><uri>file://media/materials/scripts/gazebo.material</uri><name>Gazebo/DarkGrey</name></script></material></visual></link><joint name="rotor_1_revolute_joint" type="revolute"><pose relative_to="arm_1">0.03000 0 0 0 0 0</pose><parent>arm_1</parent><child>rotor_1</child><axis><xyz>0 0 1</xyz><limit><lower>-1.79769e+308</lower><upper>1.79769e+308</upper></limit><dynamics><damping>1.00e-05</damping></dynamics></axis></joint><link name="arm_2"><pose>-0.05500 0.00000 0.00500 0 0 3.14159</pose><inertial><mass>0.000864</mass><inertia><ixx>1.29600000e-09</ixx><iyy>2.59848000e-07</iyy><izz>2.59848000e-07</izz><ixy>0</ixy><ixz>0</ixz><iyz>0</iyz></inertia></inertial><collision name="arm_2_geom_col"><geometry><box><size>0.060000 0.003000 0.003000</size></box></geometry></collision><visual name="arm_2_geom_vis"><geometry><box><size>0.060000 0.003000 0.003000</size></box></geometry><material><script><uri>file://media/materials/scripts/gazebo.material</uri><name>Gazebo/Grey</name></script></material></visual></link><joint name="arm_2_fixed_joint" type="fixed"><parent>hull</parent><child>arm_2</child><pose>-0.02500 0.00000 0 0 0 3.14159</pose></joint><link name="rotor_2"><pose>-0.08500 0.00000 0.00500 0 0 3.14159</pose><inertial><mass>0.015000</mass><inertia><ixx>9.32187500e-07</ixx><iyy>9.32187500e-07</iyy><izz>1.80187500e-06</izz><ixy>0</ixy><ixz>0</ixz><iyz>0</iyz></inertia></inertial><collision name="rotor_2_geom_col"><geometry><cylinder><radius>0.015500</radius><length>0.005000</length></cylinder></geometry></collision><visual name="rotor_2_geom_vis"><geometry><cylinder><radius>0.015500</radius><length>0.005000</length></cylinder></geometry><material><script><uri>file://media/materials/scripts/gazebo.material</uri><name>Gazebo/DarkGrey</name></script></material></visual></link><joint name="rotor_2_revolute_joint" type="revolute"><pose relative_to="arm_2">0.03000 0 0 0 0 0</pose><parent>arm_2</parent><child>rotor_2</child><axis><xyz>0 0 1</xyz><limit><lower>-1.79769e+308</lower><upper>1.79769e+308</upper></limit><dynamics><damping>1.00e-05</damping></dynamics></axis></joint><link name="arm_3"><pose>-0.00000 -0.04250 0.00500 0 0 4.71239</pose><inertial><mass>0.000864</mass><inertia><ixx>1.29600000e-09</ixx><iyy>2.59848000e-07</iyy><izz>2.59848000e-07</izz><ixy>0</ixy><ixz>0</ixz><iyz>0</iyz></inertia></inertial><collision name="arm_3_geom_col"><geometry><box><size>0.060000 0.003000 0.003000</size></box></geometry></collision><visual name="arm_3_geom_vis"><geometry><box><size>0.060000 0.003000 0.003000</size></box></geometry><material><script><uri>file://media/materials/scripts/gazebo.material</uri><name>Gazebo/Grey</name></script></material></visual></link><joint name="arm_3_fixed_joint" type="fixed"><parent>hull</parent><child>arm_3</child><pose>-0.00000 -0.01250 0 0 0 4.71239</pose></joint><link name="rotor_3"><pose>-0.00000 -0.07250 0.00500 0 0 4.71239</pose><inertial><mass>0.015000</mass><inertia><ixx>9.32187500e-07</ixx><iyy>9.32187500e-07</iyy><izz>1.80187500e-06</izz><ixy>0</ixy><ixz>0</ixz><iyz>0</iyz></inertia></inertial><collision name="rotor_3_geom_col"><geometry><cylinder><radius>0.015500</radius><length>0.005000</length></cylinder></geometry></collision><visual name="rotor_3_geom_vis"><geometry><cylinder><radius>0.015500</radius><length>0.005000</length></cylinder></geometry><material><script><uri>file://media/materials/scripts/gazebo.material</uri><name>Gazebo/DarkGrey</name></script></material></visual></link><joint name="rotor_3_revolute_joint" type="revolute"><pose relative_to="arm_3">0.03000 0 0 0 0 0</pose><parent>arm_3</parent><child>rotor_3</child><axis><xyz>0 0 1</xyz><limit><lower>-1.79769e+308</lower><upper>1.79769e+308</upper></limit><dynamics><damping>1.00e-05</damping></dynamics></axis></joint><plugin name="trick_executor_plugin" filename="libtrick_executor_plugin.so"><zmq_port>5555</zmq_port><run_test_mode>true</run_test_mode><test_mode_radius>2.0</test_mode_radius><test_mode_angular_velocity>0.5</test_mode_angular_velocity><test_mode_altitude>1.0</test_mode_altitude></plugin></model></sdf>